Workbook

Sheet README
A1: Vector7 – Tenant Admin Pre-Configuration Template
A3: Purpose: one-time setup data for a new tenant (layout promoter). Fill the yellow cells, run the Validation sheet, then import.
A5: Sheets
A6: 1. Tenant Profile – name or company name, address, contact numbers and social links.
A7: 2. Additional Settings – App Settings (currency, sellable %, broker commission, budget alert, booking validity, sale completion window, MRP multiplier) and the instalment plan with due working days.
A8: 3. Notification Groups – email groups that users are tagged to.
A9: 4. Users – login users with role (Admin, Manager, Sales, Accountant) and notification groups; column H builds the CSV text for bulk import.
A10: 5. Approval Stages – approval stages and subtasks for Village, Town and City, with dependencies, durations and required documents.
A11: 6. Facility Master – facilities with Basic / Standard / Premium inclusion and unit costs for Village, Town and City.
A12: 7. Document Checklist – documents for Agri NOC, DTCP, BDO, Town, City, Gift Deed, RERA and Plot Sale, mapped to tasks.
A13: 8. Stage Checklist Map – Stage × Checklist counts and Task → Document mapping per area.
A14: 9. Validation – automatic checks; every row must show OK before import.
... A22: • Unit costs are indicative 2026 Tamil Nadu estimates (excl. GST) – each tenant should replace with its own rates.

Sheet Tenant Profile
A1: Tenant Profile
A2: Fill the Value column. Required fields must not be blank.
A4: Sino | B4: Section | C4: Field | D4: Value | E4: Required | F4: Data Type | G4: Format / Validation | H4: Example
A5: 1 | B5: Identity | C5: Name or Company Name | E5: Yes | F5: Text | G5: Max 100 characters | H5: Sri Murugan Promoters
A6: 2 | B6: Identity | C6: Profile Picture | E6: No | F6: Image | G6: PNG/JPG, square, min 512×512 px, max 2 MB (file name or URL) | H6: logo.png
A7: 3 | B7: Address | C7: Address Line1 | E7: Yes | F7: Text | G7: Door no., street – max 150 characters | H7: 12, South Main Street
A8: 4 | B8: Address | C8: Address Line2 | E8: No | F8: Text | G8: Area / landmark – max 150 characters | H8: Near Big Temple
A9: 5 | B9: Address | C9: Village | E9: No | F9: Text | G9: Village name if applicable | H9: Vallam
A10: 6 | B10: Address | C10: City Or Town | E10: Yes | F10: Text | G10: City or town name | H10: Thanjavur
A11: 7 | B11: Address | C11: District | E11: Yes | F11: Text | G11: District name | H11: Thanjavur
A12: 8 | B12: Address | C12: State | E12: Yes | F12: List | G12: Select from list | H12: Tamil Nadu
A13: 9 | B13: Address | C13: Pin Code | E13: Yes | F13: Number | G13: Exactly 6 digits | H13: 613001
A14: 10 | B14: Contact | C14: Contact Number | E14: Yes | F14: Phone | G14: 10-digit mobile, no +91 or spaces | H14: 9876543210
A15: 11 | B15: Contact | C15: Alternate Contact | E15: No | F15: Phone | G15: 10-digit mobile or landline with STD code | H15: 04362123456
A16: 12 | B16: Social | C16: Insta | E16: No | F16: URL | G16: https://www.instagram.com/<handle> | H16: https://www.instagram.com/example
... A20: 16 | B20: Social | C20: LinkedIn | E20: No | F20: URL | G20: https://www.linkedin.com/company/<name> | H20: https://www.linkedin.com/company/example

Sheet Additional Settings
A1: Additional Settings
A2: Importer reads columns A–F. Due Working Days applies to Instalment rows only. Description (column G) is guidance.
A4: Sino | B4: Type | C4: Item | D4: Unit | E4: Unit Value | F4: Due Working Days | G4: Description
A5: 1 | B5: App Settings | C5: Currency | D5: Code | E5: INR | G5: Currency for all amounts (ISO code)
A6: 2 | B6: App Settings | C6: Sellable SQFT % | D6: Percentage | E6: 55 | G6: Default sellable share of total land for new projects; replaced by actual road and OSR
A7: 3 | B7: App Settings | C7: Broker Commission | D7: Percentage | E7: 0.5 | G7: Commission paid to broker on sale value
A8: 4 | B8: App Settings | C8: Expense vs Budget Alert | D8: Percentage | E8: 80 | G8: Alert when spend crosses this % of budget (stage, facility, project)
A9: 5 | B9: App Settings | C9: Booking Validity | D9: Days | E9: 7 | G9: Booking expires if the 1st instalment is not paid within this period
A10: 6 | B10: App Settings | C10: Sale Completion Window | D10: Days | E10: 15 | G10: All instalments and the sale deed must fall within this window
A11: 7 | B11: App Settings | C11: MRP Multiplier | D11: Times | E11: 3 | G11: MRP per sq ft = Production cost per sq ft × this multiplier
A12: 8 | B12: Instalment | C12: 1st Instalment | D12: Percentage | E12: 30 | F12: 0 | G12: Due on booking day
A13: 9 | B13: Instalment | C13: 2nd Instalment | D13: Percentage | E13: 60 | F13: 7 | G13: Due 7 working days after booking
A14: 10 | B14: Instalment | C14: 3rd Instalment | D14: Percentage | E14: 10 | F14: 13 | G14: Due 13 working days after booking

Sheet Notification Groups
A1: Notification Groups
A2: Email only in this release. Users are tagged to groups by Group Name.
A4: Sino | B4: Group Name | C4: Type | D4: Description | E4: Active
A5: 1 | B5: Management | C5: Email | D5: Project status changes, budget alerts, paused projects | E5: Yes
A6: 2 | B6: Sales Team | C6: Email | D6: Bookings created or expiring, instalments due or overdue | E6: Yes
A7: 3 | B7: Accounts | C7: Email | D7: Receipts, expenses, budget alerts | E7: Yes

Sheet Users
A1: Users – Login Enrolment
A2: Fill one row per login user, or copy column H (with the header in H4) and paste into Users & Roles → Bulk import. Example: Ravi Kumar, ravi@example.com, 9876543210, Manager, "Management, Sales Team".
A4: Sino | B4: Full Name | C4: Email | D4: Mobile | E4: Role | F4: Notification Groups | G4: Active | H4: full_name,email,mobile,role,notification_groups
A5: 1 | H5: =IF(B5="","",B5&","&C5&","&D5&","&E5&","&CHAR(34)&F5&CHAR(34))
A6: 2 | H6: =IF(B6="","",B6&","&C6&","&D6&","&E6&","&CHAR(34)&F6&CHAR(34))
A7: 3 | H7: =IF(B7="","",B7&","&C7&","&D7&","&E7&","&CHAR(34)&F7&CHAR(34))
A8: 4 | H8: =IF(B8="","",B8&","&C8&","&D8&","&E8&","&CHAR(34)&F8&CHAR(34))
A9: 5 | H9: =IF(B9="","",B9&","&C9&","&D9&","&E9&","&CHAR(34)&F9&CHAR(34))
A10: 6 | H10: =IF(B10="","",B10&","&C10&","&D10&","&E10&","&CHAR(34)&F10&CHAR(34))
A11: 7 | H11: =IF(B11="","",B11&","&C11&","&D11&","&E11&","&CHAR(34)&F11&CHAR(34))
A12: 8 | H12: =IF(B12="","",B12&","&C12&","&D12&","&E12&","&CHAR(34)&F12&CHAR(34))
A13: 9 | H13: =IF(B13="","",B13&","&C13&","&D13&","&E13&","&CHAR(34)&F13&CHAR(34))
A14: 10 | H14: =IF(B14="","",B14&","&C14&","&D14&","&E14&","&CHAR(34)&F14&CHAR(34))
A15: 11 | H15: =IF(B15="","",B15&","&C15&","&D15&","&E15&","&CHAR(34)&F15&CHAR(34))
A16: 12 | H16: =IF(B16="","",B16&","&C16&","&D16&","&E16&","&CHAR(34)&F16&CHAR(34))
... A54: 50 | H54: =IF(B54="","",B54&","&C54&","&D54&","&E54&","&CHAR(34)&F54&CHAR(34))

Sheet Approval Stages
A1: Approval Stages – Master
A2: One row per subtask. Default Duration is editable; Depends On lists Task IDs (comma-separated).
A4: Sino | B4: Area Type | C4: Stage No | D4: Stage | E4: Task ID | F4: Short Name | G4: Subtask | H4: Depends On | I4: Responsible / Authority | J4: Output / Document | K4: Default Duration (Days) | L4: Required Doc IDs | M4: Doc Count | N4: Active
A5: 1 | B5: Village | C5: 1 | D5: Land Due Diligence | E5: V1.1 | F5: Land Records | G5: Collect patta, chitta, A-register extract, FMB sketch | I5: Owner / Surveyor | J5: Land record set | K5: 7 | L5: AGR-02, AGR-04 | M5: =IF(L5="",0,LEN(L5)-LEN(SUBSTITUTE(L5,",",""))+1) -> 2 | N5: Yes
A6: 2 | B6: Village | C6: 1 | D6: Land Due Diligence | E6: V1.2 | F6: EC 30 Yrs | G6: Obtain Encumbrance Certificate (30+ years) | I6: Owner / SRO | J6: EC | K6: 7 | L6: AGR-05 | M6: =IF(L6="",0,LEN(L6)-LEN(SUBSTITUTE(L6,",",""))+1) -> 1 | N6: Yes
A7: 3 | B7: Village | C7: 1 | D7: Land Due Diligence | E7: V1.3 | F7: Title Opinion | G7: Collect parent documents; legal title opinion | H7: V1.1, V1.2 | I7: Advocate | J7: Title opinion | K7: 10 | L7: AGR-06, DTC-04 | M7: =IF(L7="",0,LEN(L7)-LEN(SUBSTITUTE(L7,",",""))+1) -> 2 | N7: Yes
A8: 4 | B8: Village | C8: 1 | D8: Land Due Diligence | E8: V1.4 | F8: Legal Risk Check | G8: Verify no poramboke, land-ceiling, litigation or acquisition issues | H8: V1.3 | I8: Advocate / Taluk office | J8: Clearance note | K8: 7 | M8: =IF(L8="",0,LEN(L8)-LEN(SUBSTITUTE(L8,",",""))+1) -> 0 | N8: Yes
A9: 5 | B9: Village | C9: 1 | D9: Land Due Diligence | E9: V1.5 | F9: Boundary Survey | G9: Field survey and boundary fixing with neighbours | H9: V1.1 | I9: Licensed Surveyor | J9: Boundary sketch | K9: 5 | M9: =IF(L9="",0,LEN(L9)-LEN(SUBSTITUTE(L9,",",""))+1) -> 0 | N9: Yes
A10: 6 | B10: Village | C10: 2 | D10: Classification & Feasibility | E10: V2.1 | F10: Dry/Wet Check | G10: Confirm dry (punjai) vs wet (nanjai) classification | H10: V1.1 | I10: Owner / VAO | J10: Classification note | K10: 3 | L10: AGR-03, AGR-08, AGR-09 | M10: =IF(L10="",0,LEN(L10)-LEN(SUBSTITUTE(L10,",",""))+1) -> 3 | N10: Yes
A11: 7 | B11: Village | C11: 2 | D11: Classification & Feasibility | E11: V2.2 | F11: Planning Status | G11: Confirm land is in a non-planning area | H11: V1.1 | I11: DTCP (District / Regional office) | J11: Planning status | K11: 5 | M11: =IF(L11="",0,LEN(L11)-LEN(SUBSTITUTE(L11,",",""))+1) -> 0 | N11: Yes
A12: 8 | B12: Village | C12: 2 | D12: Classification & Feasibility | E12: V2.3 | F12: Buffer Check | G12: Check buffers: NH (40 m residential), water bodies, railway, airport | H12: V1.5 | I12: Surveyor / Planner | J12: Buffer check | K12: 3 | M12: =IF(L12="",0,LEN(L12)-LEN(SUBSTITUTE(L12,",",""))+1) -> 0 | N12: Yes
A13: 9 | B13: Village | C13: 2 | D13: Classification & Feasibility | E13: V2.4 | F13: Go/No-Go | G13: Go / No-Go feasibility decision | H13: V1.4, V2.1, V2.2, V2.3 | I13: Owner / Developer | J13: Decision | K13: 2 | M13: =IF(L13="",0,LEN(L13)-LEN(SUBSTITUTE(L13,",",""))+1) -> 0 | N13: Yes
A14: 10 | B14: Village | C14: 3 | D14: Change of Land Use (CLU) | E14: V3.1 | F14: CLU Application | G14: Prepare CLU application (TN CLU Rules 2017, as amended by G.O. 149 / 2026) | H14: V2.4 | I14: Owner / Consultant | J14: CLU application | K14: 5 | L14: AGR-01, AGR-12, AGR-13, AGR-14 | M14: =IF(L14="",0,LEN(L14)-LEN(SUBSTITUTE(L14,",",""))+1) -> 4 | N14: Yes
A15: 11 | B15: Village | C15: 3 | D15: Change of Land Use (CLU) | E15: V3.2 | F15: CLU Submit | G15: Submit CLU application online | H15: V3.1 | I15: Owner / Consultant | J15: Acknowledgement | K15: 1 | M15: =IF(L15="",0,LEN(L15)-LEN(SUBSTITUTE(L15,",",""))+1) -> 0 | N15: Yes
A16: 12 | B16: Village | C16: 3 | D16: Change of Land Use (CLU) | E16: V3.3 | F16: CLU Inspection | G16: Field inspection and report | H16: V3.2 | I16: DTCP (District / Regional office) / Revenue | J16: Inspection report | K16: 30 | L16: AGR-10 | M16: =IF(L16="",0,LEN(L16)-LEN(SUBSTITUTE(L16,",",""))+1) -> 1 | N16: Yes
A17: 13 | B17: Village | C17: 3 | D17: Change of Land Use (CLU) | E17: V3.4 | F17: CLU Fees | G17: Pay conversion charges | H17: V3.3 | I17: Owner | J17: Challan | K17: 3 | L17: AGR-15 | M17: =IF(L17="",0,LEN(L17)-LEN(SUBSTITUTE(L17,",",""))+1) -> 1 | N17: Yes
A18: 14 | B18: Village | C18: 3 | D18: Change of Land Use (CLU) | E18: V3.5 | F18: CLU Order | G18: Receive CLU order | H18: V3.4 | I18: DTCP (District / Regional office) | J18: CLU order | K18: 15 | L18: AGR-16 | M18: =IF(L18="",0,LEN(L18)-LEN(SUBSTITUTE(L18,",",""))+1) -> 1 | N18: Yes
A19: 15 | B19: Village | C19: 4 | D19: Layout Design | E19: V4.1 | F19: Engage Consultants | G19: Engage licensed surveyor and registered architect / planner | H19: V2.4 | I19: Owner | J19: Engagement | K19: 5 | M19: =IF(L19="",0,LEN(L19)-LEN(SUBSTITUTE(L19,",",""))+1) -> 0 | N19: Yes
A20: 16 | B20: Village | C20: 4 | D20: Layout Design | E20: V4.2 | F20: Topo Survey | G20: Topographic survey and levels | H20: V4.1, V1.5 | I20: Licensed Surveyor | J20: Topo drawing | K20: 7 | L20: DTC-06 | M20: =IF(L20="",0,LEN(L20)-LEN(SUBSTITUTE(L20,",",""))+1) -> 1 | N20: Yes
A21: 17 | B21: Village | C21: 4 | D21: Layout Design | E21: V4.3 | F21: Draft Layout | G21: Draft layout per TNCDBR 2019 (roads, OSR, public-purpose area, plots) | H21: V4.2 | I21: Architect / Planner | J21: Draft layout | K21: 10 | L21: AGR-07, DTC-07, DTC-08 | M21: =IF(L21="",0,LEN(L21)-LEN(SUBSTITUTE(L21,",",""))+1) -> 3 | N21: Yes
A22: 18 | B22: Village | C22: 4 | D22: Layout Design | E22: V4.4 | F22: Finalise Drawings | G22: Internal review and finalise drawings | H22: V4.3 | I22: Owner / Architect | J22: Final drawings | K22: 5 | M22: =IF(L22="",0,LEN(L22)-LEN(SUBSTITUTE(L22,",",""))+1) -> 0 | N22: Yes
A23: 19 | B23: Village | C23: 5 | D23: NOCs | E23: V5.1 | F23: NOC Checklist | G23: Identify NOCs required for the site | H23: V4.3 | I23: Planner | J23: NOC checklist | K23: 2 | L23: DTC-11 | M23: =IF(L23="",0,LEN(L23)-LEN(SUBSTITUTE(L23,",",""))+1) -> 1 | N23: Yes
A24: 20 | B24: Village | C24: 5 | D24: NOCs | E24: V5.2 | F24: WRD NOC | G24: WRD / PWD NOC (if near tank, river, channel) | H24: V5.1 | I24: Water Resources Dept | J24: NOC | K24: 30 | L24: AGR-11 | M24: =IF(L24="",0,LEN(L24)-LEN(SUBSTITUTE(L24,",",""))+1) -> 1 | N24: Yes
A25: 21 | B25: Village | C25: 5 | D25: NOCs | E25: V5.3 | F25: Highways NOC | G25: Highways NOC (if abutting NH / SH) | H25: V5.1 | I25: NHAI / State Highways | J25: NOC | K25: 30 | M25: =IF(L25="",0,LEN(L25)-LEN(SUBSTITUTE(L25,",",""))+1) -> 0 | N25: Yes
A26: 22 | B26: Village | C26: 5 | D26: NOCs | E26: V5.4 | F26: Local Body NOC | G26: No-objection / resolution from Village Panchayat / Panchayat Union | H26: V5.1 | I26: Village Panchayat / Panchayat Union | J26: Resolution / NOC | K26: 15 | L26: BDO-02 | M26: =IF(L26="",0,LEN(L26)-LEN(SUBSTITUTE(L26,",",""))+1) -> 1 | N26: Yes
A27: 23 | B27: Village | C27: 5 | D27: NOCs | E27: V5.5 | F27: Access Road Cert | G27: Access-road certificate (Annexure-XVII, from road register) | H27: V5.1 | I27: BDO, Panchayat Union | J27: Annexure-XVII certificate | K27: 15 | L27: DTC-09, BDO-03 | M27: =IF(L27="",0,LEN(L27)-LEN(SUBSTITUTE(L27,",",""))+1) -> 2 | N27: Yes
A28: 24 | B28: Village | C28: 6 | D28: Layout Application | E28: V6.1 | F28: Portal Registration | G28: Register on TN online planning permission portal | I28: Owner / Consultant | J28: Login | K28: 1 | M28: =IF(L28="",0,LEN(L28)-LEN(SUBSTITUTE(L28,",",""))+1) -> 0 | N28: Yes
A29: 25 | B29: Village | C29: 6 | D29: Layout Application | E29: V6.2 | F29: Submit Application | G29: Upload documents, CLU/zone order, drawings, NOCs | H29: V3.5, V4.4, V5.2, V5.3, V5.4, V5.5, V6.1 | I29: Owner / Consultant | J29: Application ID | K29: 2 | L29: DTC-01, DTC-02, DTC-03, DTC-05, DTC-10, DTC-12, BDO-01 | M29: =IF(L29="",0,LEN(L29)-LEN(SUBSTITUTE(L29,",",""))+1) -> 7 | N29: Yes
A30: 26 | B30: Village | C30: 6 | D30: Layout Application | E30: V6.3 | F30: Scrutiny Fees | G30: Pay scrutiny / processing fees | H30: V6.2 | I30: Owner | J30: Receipt | K30: 1 | L30: DTC-13 | M30: =IF(L30="",0,LEN(L30)-LEN(SUBSTITUTE(L30,",",""))+1) -> 1 | N30: Yes
A31: 27 | B31: Village | C31: 6 | D31: Layout Application | E31: V6.4 | F31: BDO Forwarding | G31: BDO scrutiny and forwarding to DTCP for technical sanction | H31: V6.3 | I31: BDO, Panchayat Union | J31: Forwarding letter | K31: 15 | L31: BDO-04 | M31: =IF(L31="",0,LEN(L31)-LEN(SUBSTITUTE(L31,",",""))+1) -> 1 | N31: Yes
A32: 28 | B32: Village | C32: 7 | D32: Scrutiny | E32: V7.1 | F32: Site Inspection | G32: Site inspection by authority | H32: V6.4 | I32: DTCP (District / Regional office) | J32: Inspection report | K32: 15 | M32: =IF(L32="",0,LEN(L32)-LEN(SUBSTITUTE(L32,",",""))+1) -> 0 | N32: Yes
A33: 29 | B33: Village | C33: 7 | D33: Scrutiny | E33: V7.2 | F33: Revise Drawings | G33: Respond to objections; submit revised drawings | H33: V7.1 | I33: Architect / Planner | J33: Revised drawings | K33: 10 | L33: DTC-14 | M33: =IF(L33="",0,LEN(L33)-LEN(SUBSTITUTE(L33,",",""))+1) -> 1 | N33: Yes
A34: 30 | B34: Village | C34: 7 | D34: Scrutiny | E34: V7.3 | F34: Scrutiny Complete | G34: Technical scrutiny complete | H34: V7.2 | I34: DTCP (District / Regional office) | J34: Scrutiny note | K34: 15 | M34: =IF(L34="",0,LEN(L34)-LEN(SUBSTITUTE(L34,",",""))+1) -> 0 | N34: Yes
A35: 31 | B35: Village | C35: 8 | D35: Charges | E35: V8.1 | F35: Demand Notice | G35: Receive demand notice | H35: V7.3 | I35: DTCP (District / Regional office) / Village Panchayat / Panchayat Union | J35: Demand notice | K35: 5 | M35: =IF(L35="",0,LEN(L35)-LEN(SUBSTITUTE(L35,",",""))+1) -> 0 | N35: Yes
A36: 32 | B36: Village | C36: 8 | D36: Charges | E36: V8.2 | F36: Pay Charges | G36: Pay development, infrastructure / amenity and OSR charges | H36: V8.1 | I36: Owner | J36: Challans | K36: 5 | L36: DTC-15, BDO-06 | M36: =IF(L36="",0,LEN(L36)-LEN(SUBSTITUTE(L36,",",""))+1) -> 2 | N36: Yes
A37: 33 | B37: Village | C37: 9 | D37: Handover (Gift Deed) | E37: V9.1 | F37: Gift Deed | G37: Register gift deed of roads and OSR to Village Panchayat / Panchayat Union (accepted by BDO) | H37: V8.2 | I37: Owner / SRO | J37: Registered gift deed | K37: 7 | L37: DTC-16, BDO-07, BDO-08, GFT-01, GFT-02, GFT-03, GFT-04, GFT-05, GFT-06, GFT-07, GFT-08, GFT-09, GFT-10 | M37: =IF(L37="",0,LEN(L37)-LEN(SUBSTITUTE(L37,",",""))+1) -> 13 | N37: Yes
A38: 34 | B38: Village | C38: 9 | D38: Handover (Gift Deed) | E38: V9.2 | F38: DTCP Sanction | G38: Receive DTCP technical sanction with LP number | H38: V9.1 | I38: DTCP (District / Regional office) | J38: Approval / LP number | K38: 15 | L38: DTC-17, BDO-05 | M38: =IF(L38="",0,LEN(L38)-LEN(SUBSTITUTE(L38,",",""))+1) -> 2 | N38: Yes
A39: 35 | B39: Village | C39: 9 | D39: Handover (Gift Deed) | E39: V9.3 | F39: BDO Final Approval | G39: Final layout approval issued by BDO (Executive Authority) under TN Panchayat Building Rules | H39: V9.2 | I39: BDO, Panchayat Union | J39: Layout approval order | K39: 15 | L39: BDO-09 | M39: =IF(L39="",0,LEN(L39)-LEN(SUBSTITUTE(L39,",",""))+1) -> 1 | N39: Yes
A40: 36 | B40: Village | C40: 10 | D40: Development Works | E40: V10.1 | F40: Roads | G40: Form roads as per approved widths | H40: V9.3 | I40: Contractor | J40: Roads | K40: 45 | M40: =IF(L40="",0,LEN(L40)-LEN(SUBSTITUTE(L40,",",""))+1) -> 0 | N40: Yes
A41: 37 | B41: Village | C41: 10 | D41: Development Works | E41: V10.2 | F41: Drains | G41: Storm-water drains / culverts | H41: V9.3 | I41: Contractor | J41: Drains | K41: 30 | M41: =IF(L41="",0,LEN(L41)-LEN(SUBSTITUTE(L41,",",""))+1) -> 0 | N41: Yes
...

Sheet Facility Master
A1: Facility Master
A2: Tier flags: Y = included · Opt = optional (not costed) · - = not included. Unit costs in ₹, excl. GST.
A4: Sino | B4: Facility ID | C4: Category | D4: Facility | E4: Specification | F4: Unit | G4: Basic | H4: Standard | I4: Premium | J4: Statutory | K4: Village Unit Cost (₹) | L4: Town Unit Cost (₹) | M4: City Unit Cost (₹) | N4: Active
A5: 1 | B5: F01 | C5: Roads | D5: Gravel / WBM road | E5: Compacted gravel with WBM layers | F5: sq m | G5: Y | H5: - | I5: - | J5: Yes | K5: 450 | L5: 495 | M5: 562 | N5: Yes
A6: 2 | B6: F02 | C6: Roads | D6: Bituminous (BT) road | E6: WMM base + 50 mm BT surface | F6: sq m | G6: - | H6: Y | I6: - | J6: Yes | K6: 900 | L6: 990 | M6: 1125 | N6: Yes
A7: 3 | B7: F03 | C7: Roads | D7: Cement concrete (CC) road | E7: M30 concrete, 200 mm, on GSB base | F7: sq m | G7: - | H7: - | I7: Y | J7: Yes | K7: 1600 | L7: 1760 | M7: 2000 | N7: Yes
A8: 4 | B8: F04 | C8: Roads | D8: Kerb stones | E8: Precast kerb both sides | F8: running m | G8: - | H8: Y | I8: Y | J8: No | K8: 450 | L8: 495 | M8: 562 | N8: Yes
A9: 5 | B9: F05 | C9: Roads | D9: Footpath with paver blocks | E9: 1.2 m wide, both sides | F9: running m | G9: - | H9: - | I9: Y | J9: No | K9: 1400 | L9: 1540 | M9: 1750 | N9: Yes
A10: 6 | B10: F06 | C10: Drainage | D10: Open PCC / brick drain | E10: Lined open drain, both sides | F10: running m | G10: Y | H10: - | I10: - | J10: Yes | K10: 1200 | L10: 1320 | M10: 1500 | N10: Yes
A11: 7 | B11: F07 | C11: Drainage | D11: Covered RCC drain | E11: RCC drain with cover slabs, both sides | F11: running m | G11: - | H11: Y | I11: Y | J11: Yes | K11: 3500 | L11: 3850 | M11: 4375 | N11: Yes
A12: 8 | B12: F08 | C12: Drainage | D12: Road crossing culverts | E12: RCC pipe / box culvert | F12: nos | G12: Y | H12: Y | I12: Y | J12: Yes | K12: 60000 | L12: 66000 | M12: 75000 | N12: Yes
A13: 9 | B13: F09 | C13: Drainage | D13: Underground sewer line (UGD) | E13: PVC/SW pipe with manholes | F13: running m | G13: - | H13: - | I13: Y | J13: No | K13: 4500 | L13: 4950 | M13: 5625 | N13: Yes
A14: 10 | B14: F10 | C14: Drainage | D14: Sewage treatment plant (package) | E14: Packaged STP | F14: KLD | G14: - | H14: - | I14: Y | J14: No | K14: 80000 | L14: 88000 | M14: 100000 | N14: Yes
A15: 11 | B15: F11 | C15: Water | D15: Borewell with submersible pump | E15: Common source | F15: nos | G15: Y | H15: Y | I15: Y | J15: No | K15: 250000 | L15: 275000 | M15: 312500 | N15: Yes
A16: 12 | B16: F12 | C16: Water | D16: Overhead tank (OHT) | E16: RCC / sintex elevated storage | F16: litres | G16: - | H16: Y | I16: Y | J16: No | K16: 20 | L16: 22 | M16: 25 | N16: Yes
... A44: 40 | B44: F40 | C44: Common | D44: Solid waste collection point | E44: Bin platform with shed | F44: nos | G44: Y | H44: Y | I44: Y | J44: No | K44: 50000 | L44: 55000 | M44: 62500 | N44: Yes
A46: Town / City costs pre-filled at 1.10× / 1.25× the Village rate – overwrite with the tenant's own rates.

Sheet Document Checklist
A1: Document Checklist – Master
A2: One row per document, mapped to a Stage and to the exact Task ID for each area (N/A = not applicable).
A4: Sino | B4: Checklist | C4: Doc ID | D4: Applies To | E4: Document / Item | F4: Issued By / Source | G4: Submission Format | H4: Mandatory | I4: Condition / Remarks | J4: Stage No | K4: Stage | L4: Village Task ID | M4: Town Task ID | N4: City Task ID | O4: Active
A5: 1 | B5: Agri NOC | C5: AGR-01 | D5: All | E5: Land-use conversion application form | F5: Owner / Consultant | G5: Online upload | H5: Yes | I5: Under TN CLU Rules 2017 (as amended) or zone reclassification | J5: 3 | K5: Change of Land Use / Zone Conversion | L5: V3.1 | M5: T3.1 | N5: C3.1 | O5: Yes
A6: 2 | B6: Agri NOC | C6: AGR-02 | D6: All | E6: Patta and Chitta | F6: Revenue (e-Services) | G6: Online copy | H6: Yes | J6: 1 | K6: Land Due Diligence | L6: V1.1 | M6: T1.1 | N6: C1.1 | O6: Yes
A7: 3 | B7: Agri NOC | C7: AGR-03 | D7: All | E7: A-register / Adangal extract | F7: Revenue (e-Services) | G7: Online copy | H7: Yes | I7: Shows dry (punjai) / wet (nanjai) classification | J7: 2 | K7: Classification & Feasibility | L7: V2.1 | M7: T2.1 | N7: C2.1 | O7: Yes
A8: 4 | B8: Agri NOC | C8: AGR-04 | D8: All | E8: FMB sketch | F8: Survey dept | G8: Online copy | H8: Yes | J8: 1 | K8: Land Due Diligence | L8: V1.1 | M8: T1.1 | N8: C1.1 | O8: Yes
A9: 5 | B9: Agri NOC | C9: AGR-05 | D9: All | E9: Encumbrance Certificate (30+ years) | F9: Sub-Registrar / TNREGINET | G9: Online copy | H9: Yes | J9: 1 | K9: Land Due Diligence | L9: V1.2 | M9: T1.2 | N9: C1.2 | O9: Yes
A10: 6 | B10: Agri NOC | C10: AGR-06 | D10: All | E10: Sale deed / parent title documents | F10: Owner | G10: Self-attested copy | H10: Yes | J10: 1 | K10: Land Due Diligence | L10: V1.3 | M10: T1.3 | N10: C1.3 | O10: Yes
A11: 7 | B11: Agri NOC | C11: AGR-07 | D11: All | E11: Site location sketch with surroundings | F11: Licensed Surveyor | G11: Drawing (PDF) | H11: Yes | I11: Show roads, water bodies, adjoining uses within 500 m | J11: 4 | K11: Layout Design | L11: V4.3 | M11: T4.3 | N11: C4.3 | O11: Yes
A12: 8 | B12: Agri NOC | C12: AGR-08 | D12: All | E12: Site photographs (all sides) | F12: Owner | G12: Images | H12: Yes | I12: Geo-tagged preferred | J12: 2 | K12: Classification & Feasibility | L12: V2.1 | M12: T2.1 | N12: C2.1 | O12: Yes
A13: 9 | B13: Agri NOC | C13: AGR-09 | D13: All | E13: Land classification certificate | F13: VAO / Tahsildar | G13: Original | H13: Conditional | I13: If classification is disputed or not clear in A-register | J13: 2 | K13: Classification & Feasibility | L13: V2.1 | M13: T2.1 | N13: C2.1 | O13: Yes
A14: 10 | B14: Agri NOC | C14: AGR-10 | D14: All | E14: Agriculture Department NOC | F14: Joint Director of Agriculture | G14: Original | H14: Conditional | I14: Wet land or where required; dry land in non-planning areas no longer needs Agri report after G.O. 149 (2026) | J14: 3 | K14: Change of Land Use / Zone Conversion | L14: V3.3 | M14: T3.3 | N14: C3.3 | O14: Yes
A15: 11 | B15: Agri NOC | C15: AGR-11 | D15: All | E15: WRD / PWD NOC | F15: Water Resources Dept | G15: Original | H15: Conditional | I15: If near tank, channel, river or in catchment | J15: 5 | K15: NOCs | L15: V5.2 | M15: T5.2 | N15: C5.2 | O15: Yes
A16: 12 | B16: Agri NOC | C16: AGR-12 | D16: All | E16: Affidavit – no tenancy / not irrigated / no dispute | F16: Owner (notarised) | G16: Original | H16: Yes | J16: 3 | K16: Change of Land Use / Zone Conversion | L16: V3.1 | M16: T3.1 | N16: C3.1 | O16: Yes
A17: 13 | B17: Agri NOC | C17: AGR-13 | D17: All | E17: Owner ID and address proof (Aadhaar, PAN) | F17: Owner | G17: Self-attested copy | H17: Yes | J17: 3 | K17: Change of Land Use / Zone Conversion | L17: V3.1 | M17: T3.1 | N17: C3.1 | O17: Yes
A18: 14 | B18: Agri NOC | C18: AGR-14 | D18: All | E18: Power of Attorney | F18: Owner / SRO | G18: Registered copy | H18: Conditional | I18: If applicant is not the owner | J18: 3 | K18: Change of Land Use / Zone Conversion | L18: V3.1 | M18: T3.1 | N18: C3.1 | O18: Yes
A19: 15 | B19: Agri NOC | C19: AGR-15 | D19: All | E19: Conversion fee challan | F19: Owner | G19: Receipt | H19: Yes | J19: 3 | K19: Change of Land Use / Zone Conversion | L19: V3.4 | M19: T3.5 | N19: C3.5 | O19: Yes
A20: 16 | B20: Agri NOC | C20: AGR-16 | D20: All | E20: CLU / Reclassification order | F20: DTCP / Govt (H&UD) | G20: Original | H20: Yes | I20: Final output of this checklist | J20: 3 | K20: Change of Land Use / Zone Conversion | L20: V3.5 | M20: T3.6 | N20: C3.6 | O20: Yes
A21: 17 | B21: DTCP Approval | C21: DTC-01 | D21: All | E21: Layout application form (online portal) | F21: Owner / Consultant | G21: Online upload | H21: Yes | J21: 6 | K21: Layout Application | L21: V6.2 | M21: T6.2 | N21: C6.2 | O21: Yes
A22: 18 | B22: DTCP Approval | C22: DTC-02 | D22: All | E22: Ownership set – sale deed, patta, chitta, A-register, FMB | F22: Owner | G22: Self-attested copy | H22: Yes | J22: 6 | K22: Layout Application | L22: V6.2 | M22: T6.2 | N22: C6.2 | O22: Yes
A23: 19 | B23: DTCP Approval | C23: DTC-03 | D23: All | E23: Encumbrance Certificate (latest) | F23: TNREGINET | G23: Online copy | H23: Yes | J23: 6 | K23: Layout Application | L23: V6.2 | M23: T6.2 | N23: C6.2 | O23: Yes
A24: 20 | B24: DTCP Approval | C24: DTC-04 | D24: All | E24: Legal title opinion | F24: Panel advocate | G24: Original | H24: Yes | I24: Advocate on local body / nationalised bank panel | J24: 1 | K24: Land Due Diligence | L24: V1.3 | M24: T1.3 | N24: C1.3 | O24: Yes
A25: 21 | B25: DTCP Approval | C25: DTC-05 | D25: All | E25: CLU order / zone certificate | F25: DTCP / LPA | G25: Copy | H25: Yes | J25: 6 | K25: Layout Application | L25: V6.2 | M25: T6.2 | N25: C6.2 | O25: Yes
A26: 22 | B26: DTCP Approval | C26: DTC-06 | D26: All | E26: Topographic survey drawing | F26: Licensed Surveyor | G26: Drawing (PDF + CAD) | H26: Yes | J26: 4 | K26: Layout Design | L26: V4.2 | M26: T4.2 | N26: C4.2 | O26: Yes
A27: 23 | B27: DTCP Approval | C27: DTC-07 | D27: All | E27: Layout plan – roads, OSR, public purpose, plot schedule | F27: Registered Architect / Planner | G27: Drawing (PDF + CAD) | H27: Yes | I27: As per TNCDBR 2019 | J27: 4 | K27: Layout Design | L27: V4.3 | M27: T4.3 | N27: C4.3 | O27: Yes
A28: 24 | B28: DTCP Approval | C28: DTC-08 | D28: All | E28: Key plan / location plan | F28: Architect | G28: Drawing (PDF) | H28: Yes | J28: 4 | K28: Layout Design | L28: V4.3 | M28: T4.3 | N28: C4.3 | O28: Yes
A29: 25 | B29: DTCP Approval | C29: DTC-09 | D29: All | E29: Access-road certificate (Annexure-XVII) | F29: BDO / EO / Commissioner | G29: Original | H29: Yes | I29: Based on local body road register | J29: 5 | K29: NOCs | L29: V5.5 | M29: T5.5 | N29: C5.5 | O29: Yes
A30: 26 | B30: DTCP Approval | C30: DTC-10 | D30: All | E30: Undertaking in Form-C (Annexure-III, TNCDBR 2019) | F30: Owner (notarised) | G30: Original | H30: Yes | J30: 6 | K30: Layout Application | L30: V6.2 | M30: T6.2 | N30: C6.2 | O30: Yes
A31: 27 | B31: DTCP Approval | C31: DTC-11 | D31: All | E31: Applicable NOCs (WRD, Highways, others) | F31: Respective depts | G31: Original | H31: Conditional | I31: As identified in NOC checklist | J31: 5 | K31: NOCs | L31: V5.1 | M31: T5.1 | N31: C5.1 | O31: Yes
A32: 28 | B32: DTCP Approval | C32: DTC-12 | D32: All | E32: Surveyor / Architect registration certificates | F32: Consultants | G32: Copy | H32: Yes | J32: 6 | K32: Layout Application | L32: V6.2 | M32: T6.2 | N32: C6.2 | O32: Yes
A33: 29 | B33: DTCP Approval | C33: DTC-13 | D33: All | E33: Scrutiny fee receipt | F33: Portal | G33: Receipt | H33: Yes | J33: 6 | K33: Layout Application | L33: V6.3 | M33: T6.3 | N33: C6.3 | O33: Yes
A34: 30 | B34: DTCP Approval | C34: DTC-14 | D34: All | E34: Compliance reply / revised drawings | F34: Architect | G34: Drawing (PDF) | H34: Conditional | I34: If objections raised at scrutiny | J34: 7 | K34: Scrutiny | L34: V7.2 | M34: T7.2 | N34: C7.2 | O34: Yes
A35: 31 | B35: DTCP Approval | C35: DTC-15 | D35: All | E35: Payment receipts – development, infrastructure & amenities, OSR charges | F35: Owner | G35: Receipt | H35: Yes | I35: As per demand notice | J35: 8 | K35: Charges | L35: V8.2 | M35: T8.2 | N35: C8.2 | O35: Yes
A36: 32 | B36: DTCP Approval | C36: DTC-16 | D36: All | E36: Registered gift deed copy (roads & OSR) | F36: SRO | G36: Certified copy | H36: Yes | I36: See Gift Deed checklist | J36: 9 | K36: Handover (Gift Deed) | L36: V9.1 | M36: T9.1 | N36: C9.1 | O36: Yes
A37: 33 | B37: DTCP Approval | C37: DTC-17 | D37: All | E37: Approval proceedings with LP number | F37: DTCP | G37: Original | H37: Yes | I37: Verify on onlineppa.tn.gov.in | J37: 9 | K37: Handover (Gift Deed) | L37: V9.2 | M37: T9.2 | N37: C9.2 | O37: Yes
A38: 34 | B38: Local BDO Approval | C38: BDO-01 | D38: Village | E38: Application routed through Panchayat Union | F38: Owner | G38: Online upload / Hard copy | H38: Yes | I38: DTCP accepts layouts only via the local body | J38: 6 | K38: Layout Application | L38: V6.2 | M38: N/A | N38: N/A | O38: Yes
A39: 35 | B39: Local BDO Approval | C39: BDO-02 | D39: Village | E39: Village Panchayat resolution / no-objection | F39: Village Panchayat | G39: Original | H39: Yes | J39: 5 | K39: NOCs | L39: V5.4 | M39: N/A | N39: N/A | O39: Yes
A40: 36 | B40: Local BDO Approval | C40: BDO-03 | D40: Village | E40: Access-road certificate (Annexure-XVII) from road register | F40: BDO, Panchayat Union | G40: Original | H40: Yes | J40: 5 | K40: NOCs | L40: V5.5 | M40: N/A | N40: N/A | O40: Yes
A41: 37 | B41: Local BDO Approval | C41: BDO-04 | D41: Village | E41: BDO scrutiny and forwarding letter to DTCP | F41: BDO, Panchayat Union | G41: Letter | H41: Yes | J41: 6 | K41: Layout Application | L41: V6.4 | M41: N/A | N41: N/A | O41: Yes
...

Sheet Stage Checklist Map
A1: Stage × Checklist Map
A2: Top: number of documents per Stage and Checklist (live from Document Checklist). Bottom: flat Task → Document mapping for import.
A4: Stage No | B4: Stage | C4: Agri NOC | D4: DTCP Approval | E4: Local BDO Approval | F4: Town Approval | G4: City Approval | H4: Gift Deed | I4: RERA | J4: Plot Sale | K4: Total
A5: 1 | B5: Land Due Diligence | C5: =COUNTIFS('Document Checklist'!$J$5:$J$1000,$A5,'Document Checklist'!$B$5:$B$1000,"Agri NOC") -> 4 | D5: =COUNTIFS('Document Checklist'!$J$5:$J$1000,$A5,'Document Checklist'!$B$5:$B$1000,"DTCP Approval") -> 1 | E5: =COUNTIFS('Document Checklist'!$J$5:$J$1000,$A5,'Document Checklist'!$B$5:$B$1000,"Local BDO Approval") -> 0 | F5: =COUNTIFS('Document Checklist'!$J$5:$J$1000,$A5,'Document Checklist'!$B$5:$B$1000,"Town Approval") -> 0 | G5: =COUNTIFS('Document Checklist'!$J$5:$J$1000,$A5,'Document Checklist'!$B$5:$B$1000,"City Approval") -> 0 | H5: =COUNTIFS('Document Checklist'!$J$5:$J$1000,$A5,'Document Checklist'!$B$5:$B$1000,"Gift Deed") -> 0 | I5: =COUNTIFS('Document Checklist'!$J$5:$J$1000,$A5,'Document Checklist'!$B$5:$B$1000,"RERA") -> 0 | J5: =COUNTIFS('Document Checklist'!$J$5:$J$1000,$A5,'Document Checklist'!$B$5:$B$1000,"Plot Sale") -> 0 | K5: =SUM(C5:J5) -> 5
A6: 2 | B6: Classification & Feasibility | C6: =COUNTIFS('Document Checklist'!$J$5:$J$1000,$A6,'Document Checklist'!$B$5:$B$1000,"Agri NOC") -> 3 | D6: =COUNTIFS('Document Checklist'!$J$5:$J$1000,$A6,'Document Checklist'!$B$5:$B$1000,"DTCP Approval") -> 0 | E6: =COUNTIFS('Document Checklist'!$J$5:$J$1000,$A6,'Document Checklist'!$B$5:$B$1000,"Local BDO Approval") -> 0 | F6: =COUNTIFS('Document Checklist'!$J$5:$J$1000,$A6,'Document Checklist'!$B$5:$B$1000,"Town Approval") -> 1 | G6: =COUNTIFS('Document Checklist'!$J$5:$J$1000,$A6,'Document Checklist'!$B$5:$B$1000,"City Approval") -> 1 | H6: =COUNTIFS('Document Checklist'!$J$5:$J$1000,$A6,'Document Checklist'!$B$5:$B$1000,"Gift Deed") -> 0 | I6: =COUNTIFS('Document Checklist'!$J$5:$J$1000,$A6,'Document Checklist'!$B$5:$B$1000,"RERA") -> 0 | J6: =COUNTIFS('Document Checklist'!$J$5:$J$1000,$A6,'Document Checklist'!$B$5:$B$1000,"Plot Sale") -> 0 | K6: =SUM(C6:J6) -> 5
A7: 3 | B7: Change of Land Use / Zone Conversion | C7: =COUNTIFS('Document Checklist'!$J$5:$J$1000,$A7,'Document Checklist'!$B$5:$B$1000,"Agri NOC") -> 7 | D7: =COUNTIFS('Document Checklist'!$J$5:$J$1000,$A7,'Document Checklist'!$B$5:$B$1000,"DTCP Approval") -> 0 | E7: =COUNTIFS('Document Checklist'!$J$5:$J$1000,$A7,'Document Checklist'!$B$5:$B$1000,"Local BDO Approval") -> 0 | F7: =COUNTIFS('Document Checklist'!$J$5:$J$1000,$A7,'Document Checklist'!$B$5:$B$1000,"Town Approval") -> 1 | G7: =COUNTIFS('Document Checklist'!$J$5:$J$1000,$A7,'Document Checklist'!$B$5:$B$1000,"City Approval") -> 1 | H7: =COUNTIFS('Document Checklist'!$J$5:$J$1000,$A7,'Document Checklist'!$B$5:$B$1000,"Gift Deed") -> 0 | I7: =COUNTIFS('Document Checklist'!$J$5:$J$1000,$A7,'Document Checklist'!$B$5:$B$1000,"RERA") -> 0 | J7: =COUNTIFS('Document Checklist'!$J$5:$J$1000,$A7,'Document Checklist'!$B$5:$B$1000,"Plot Sale") -> 0 | K7: =SUM(C7:J7) -> 9
A8: 4 | B8: Layout Design | C8: =COUNTIFS('Document Checklist'!$J$5:$J$1000,$A8,'Document Checklist'!$B$5:$B$1000,"Agri NOC") -> 1 | D8: =COUNTIFS('Document Checklist'!$J$5:$J$1000,$A8,'Document Checklist'!$B$5:$B$1000,"DTCP Approval") -> 3 | E8: =COUNTIFS('Document Checklist'!$J$5:$J$1000,$A8,'Document Checklist'!$B$5:$B$1000,"Local BDO Approval") -> 0 | F8: =COUNTIFS('Document Checklist'!$J$5:$J$1000,$A8,'Document Checklist'!$B$5:$B$1000,"Town Approval") -> 0 | G8: =COUNTIFS('Document Checklist'!$J$5:$J$1000,$A8,'Document Checklist'!$B$5:$B$1000,"City Approval") -> 0 | H8: =COUNTIFS('Document Checklist'!$J$5:$J$1000,$A8,'Document Checklist'!$B$5:$B$1000,"Gift Deed") -> 0 | I8: =COUNTIFS('Document Checklist'!$J$5:$J$1000,$A8,'Document Checklist'!$B$5:$B$1000,"RERA") -> 0 | J8: =COUNTIFS('Document Checklist'!$J$5:$J$1000,$A8,'Document Checklist'!$B$5:$B$1000,"Plot Sale") -> 0 | K8: =SUM(C8:J8) -> 4
A9: 5 | B9: NOCs | C9: =COUNTIFS('Document Checklist'!$J$5:$J$1000,$A9,'Document Checklist'!$B$5:$B$1000,"Agri NOC") -> 1 | D9: =COUNTIFS('Document Checklist'!$J$5:$J$1000,$A9,'Document Checklist'!$B$5:$B$1000,"DTCP Approval") -> 2 | E9: =COUNTIFS('Document Checklist'!$J$5:$J$1000,$A9,'Document Checklist'!$B$5:$B$1000,"Local BDO Approval") -> 2 | F9: =COUNTIFS('Document Checklist'!$J$5:$J$1000,$A9,'Document Checklist'!$B$5:$B$1000,"Town Approval") -> 3 | G9: =COUNTIFS('Document Checklist'!$J$5:$J$1000,$A9,'Document Checklist'!$B$5:$B$1000,"City Approval") -> 6 | H9: =COUNTIFS('Document Checklist'!$J$5:$J$1000,$A9,'Document Checklist'!$B$5:$B$1000,"Gift Deed") -> 0 | I9: =COUNTIFS('Document Checklist'!$J$5:$J$1000,$A9,'Document Checklist'!$B$5:$B$1000,"RERA") -> 0 | J9: =COUNTIFS('Document Checklist'!$J$5:$J$1000,$A9,'Document Checklist'!$B$5:$B$1000,"Plot Sale") -> 0 | K9: =SUM(C9:J9) -> 14
A10: 6 | B10: Layout Application | C10: =COUNTIFS('Document Checklist'!$J$5:$J$1000,$A10,'Document Checklist'!$B$5:$B$1000,"Agri NOC") -> 0 | D10: =COUNTIFS('Document Checklist'!$J$5:$J$1000,$A10,'Document Checklist'!$B$5:$B$1000,"DTCP Approval") -> 7 | E10: =COUNTIFS('Document Checklist'!$J$5:$J$1000,$A10,'Document Checklist'!$B$5:$B$1000,"Local BDO Approval") -> 2 | F10: =COUNTIFS('Document Checklist'!$J$5:$J$1000,$A10,'Document Checklist'!$B$5:$B$1000,"Town Approval") -> 2 | G10: =COUNTIFS('Document Checklist'!$J$5:$J$1000,$A10,'Document Checklist'!$B$5:$B$1000,"City Approval") -> 2 | H10: =COUNTIFS('Document Checklist'!$J$5:$J$1000,$A10,'Document Checklist'!$B$5:$B$1000,"Gift Deed") -> 0 | I10: =COUNTIFS('Document Checklist'!$J$5:$J$1000,$A10,'Document Checklist'!$B$5:$B$1000,"RERA") -> 0 | J10: =COUNTIFS('Document Checklist'!$J$5:$J$1000,$A10,'Document Checklist'!$B$5:$B$1000,"Plot Sale") -> 0 | K10: =SUM(C10:J10) -> 13
A11: 7 | B11: Scrutiny | C11: =COUNTIFS('Document Checklist'!$J$5:$J$1000,$A11,'Document Checklist'!$B$5:$B$1000,"Agri NOC") -> 0 | D11: =COUNTIFS('Document Checklist'!$J$5:$J$1000,$A11,'Document Checklist'!$B$5:$B$1000,"DTCP Approval") -> 1 | E11: =COUNTIFS('Document Checklist'!$J$5:$J$1000,$A11,'Document Checklist'!$B$5:$B$1000,"Local BDO Approval") -> 0 | F11: =COUNTIFS('Document Checklist'!$J$5:$J$1000,$A11,'Document Checklist'!$B$5:$B$1000,"Town Approval") -> 0 | G11: =COUNTIFS('Document Checklist'!$J$5:$J$1000,$A11,'Document Checklist'!$B$5:$B$1000,"City Approval") -> 0 | H11: =COUNTIFS('Document Checklist'!$J$5:$J$1000,$A11,'Document Checklist'!$B$5:$B$1000,"Gift Deed") -> 0 | I11: =COUNTIFS('Document Checklist'!$J$5:$J$1000,$A11,'Document Checklist'!$B$5:$B$1000,"RERA") -> 0 | J11: =COUNTIFS('Document Checklist'!$J$5:$J$1000,$A11,'Document Checklist'!$B$5:$B$1000,"Plot Sale") -> 0 | K11: =SUM(C11:J11) -> 1
A12: 8 | B12: Charges | C12: =COUNTIFS('Document Checklist'!$J$5:$J$1000,$A12,'Document Checklist'!$B$5:$B$1000,"Agri NOC") -> 0 | D12: =COUNTIFS('Document Checklist'!$J$5:$J$1000,$A12,'Document Checklist'!$B$5:$B$1000,"DTCP Approval") -> 1 | E12: =COUNTIFS('Document Checklist'!$J$5:$J$1000,$A12,'Document Checklist'!$B$5:$B$1000,"Local BDO Approval") -> 1 | F12: =COUNTIFS('Document Checklist'!$J$5:$J$1000,$A12,'Document Checklist'!$B$5:$B$1000,"Town Approval") -> 1 | G12: =COUNTIFS('Document Checklist'!$J$5:$J$1000,$A12,'Document Checklist'!$B$5:$B$1000,"City Approval") -> 1 | H12: =COUNTIFS('Document Checklist'!$J$5:$J$1000,$A12,'Document Checklist'!$B$5:$B$1000,"Gift Deed") -> 0 | I12: =COUNTIFS('Document Checklist'!$J$5:$J$1000,$A12,'Document Checklist'!$B$5:$B$1000,"RERA") -> 0 | J12: =COUNTIFS('Document Checklist'!$J$5:$J$1000,$A12,'Document Checklist'!$B$5:$B$1000,"Plot Sale") -> 0 | K12: =SUM(C12:J12) -> 4
A13: 9 | B13: Handover (Gift Deed) | C13: =COUNTIFS('Document Checklist'!$J$5:$J$1000,$A13,'Document Checklist'!$B$5:$B$1000,"Agri NOC") -> 0 | D13: =COUNTIFS('Document Checklist'!$J$5:$J$1000,$A13,'Document Checklist'!$B$5:$B$1000,"DTCP Approval") -> 2 | E13: =COUNTIFS('Document Checklist'!$J$5:$J$1000,$A13,'Document Checklist'!$B$5:$B$1000,"Local BDO Approval") -> 4 | F13: =COUNTIFS('Document Checklist'!$J$5:$J$1000,$A13,'Document Checklist'!$B$5:$B$1000,"Town Approval") -> 1 | G13: =COUNTIFS('Document Checklist'!$J$5:$J$1000,$A13,'Document Checklist'!$B$5:$B$1000,"City Approval") -> 1 | H13: =COUNTIFS('Document Checklist'!$J$5:$J$1000,$A13,'Document Checklist'!$B$5:$B$1000,"Gift Deed") -> 10 | I13: =COUNTIFS('Document Checklist'!$J$5:$J$1000,$A13,'Document Checklist'!$B$5:$B$1000,"RERA") -> 0 | J13: =COUNTIFS('Document Checklist'!$J$5:$J$1000,$A13,'Document Checklist'!$B$5:$B$1000,"Plot Sale") -> 0 | K13: =SUM(C13:J13) -> 18
A14: 10 | B14: Development Works | C14: =COUNTIFS('Document Checklist'!$J$5:$J$1000,$A14,'Document Checklist'!$B$5:$B$1000,"Agri NOC") -> 0 | D14: =COUNTIFS('Document Checklist'!$J$5:$J$1000,$A14,'Document Checklist'!$B$5:$B$1000,"DTCP Approval") -> 0 | E14: =COUNTIFS('Document Checklist'!$J$5:$J$1000,$A14,'Document Checklist'!$B$5:$B$1000,"Local BDO Approval") -> 1 | F14: =COUNTIFS('Document Checklist'!$J$5:$J$1000,$A14,'Document Checklist'!$B$5:$B$1000,"Town Approval") -> 1 | G14: =COUNTIFS('Document Checklist'!$J$5:$J$1000,$A14,'Document Checklist'!$B$5:$B$1000,"City Approval") -> 1 | H14: =COUNTIFS('Document Checklist'!$J$5:$J$1000,$A14,'Document Checklist'!$B$5:$B$1000,"Gift Deed") -> 0 | I14: =COUNTIFS('Document Checklist'!$J$5:$J$1000,$A14,'Document Checklist'!$B$5:$B$1000,"RERA") -> 0 | J14: =COUNTIFS('Document Checklist'!$J$5:$J$1000,$A14,'Document Checklist'!$B$5:$B$1000,"Plot Sale") -> 0 | K14: =SUM(C14:J14) -> 3
A15: 11 | B15: Final Approval & Release | C15: =COUNTIFS('Document Checklist'!$J$5:$J$1000,$A15,'Document Checklist'!$B$5:$B$1000,"Agri NOC") -> 0 | D15: =COUNTIFS('Document Checklist'!$J$5:$J$1000,$A15,'Document Checklist'!$B$5:$B$1000,"DTCP Approval") -> 0 | E15: =COUNTIFS('Document Checklist'!$J$5:$J$1000,$A15,'Document Checklist'!$B$5:$B$1000,"Local BDO Approval") -> 1 | F15: =COUNTIFS('Document Checklist'!$J$5:$J$1000,$A15,'Document Checklist'!$B$5:$B$1000,"Town Approval") -> 1 | G15: =COUNTIFS('Document Checklist'!$J$5:$J$1000,$A15,'Document Checklist'!$B$5:$B$1000,"City Approval") -> 1 | H15: =COUNTIFS('Document Checklist'!$J$5:$J$1000,$A15,'Document Checklist'!$B$5:$B$1000,"Gift Deed") -> 0 | I15: =COUNTIFS('Document Checklist'!$J$5:$J$1000,$A15,'Document Checklist'!$B$5:$B$1000,"RERA") -> 0 | J15: =COUNTIFS('Document Checklist'!$J$5:$J$1000,$A15,'Document Checklist'!$B$5:$B$1000,"Plot Sale") -> 1 | K15: =SUM(C15:J15) -> 4
A16: 12 | B16: RERA | C16: =COUNTIFS('Document Checklist'!$J$5:$J$1000,$A16,'Document Checklist'!$B$5:$B$1000,"Agri NOC") -> 0 | D16: =COUNTIFS('Document Checklist'!$J$5:$J$1000,$A16,'Document Checklist'!$B$5:$B$1000,"DTCP Approval") -> 0 | E16: =COUNTIFS('Document Checklist'!$J$5:$J$1000,$A16,'Document Checklist'!$B$5:$B$1000,"Local BDO Approval") -> 0 | F16: =COUNTIFS('Document Checklist'!$J$5:$J$1000,$A16,'Document Checklist'!$B$5:$B$1000,"Town Approval") -> 0 | G16: =COUNTIFS('Document Checklist'!$J$5:$J$1000,$A16,'Document Checklist'!$B$5:$B$1000,"City Approval") -> 0 | H16: =COUNTIFS('Document Checklist'!$J$5:$J$1000,$A16,'Document Checklist'!$B$5:$B$1000,"Gift Deed") -> 0 | I16: =COUNTIFS('Document Checklist'!$J$5:$J$1000,$A16,'Document Checklist'!$B$5:$B$1000,"RERA") -> 15 | J16: =COUNTIFS('Document Checklist'!$J$5:$J$1000,$A16,'Document Checklist'!$B$5:$B$1000,"Plot Sale") -> 1 | K16: =SUM(C16:J16) -> 16
A17: 13 | B17: Sub-division & Sale | C17: =COUNTIFS('Document Checklist'!$J$5:$J$1000,$A17,'Document Checklist'!$B$5:$B$1000,"Agri NOC") -> 0 | D17: =COUNTIFS('Document Checklist'!$J$5:$J$1000,$A17,'Document Checklist'!$B$5:$B$1000,"DTCP Approval") -> 0 | E17: =COUNTIFS('Document Checklist'!$J$5:$J$1000,$A17,'Document Checklist'!$B$5:$B$1000,"Local BDO Approval") -> 0 | F17: =COUNTIFS('Document Checklist'!$J$5:$J$1000,$A17,'Document Checklist'!$B$5:$B$1000,"Town Approval") -> 0 | G17: =COUNTIFS('Document Checklist'!$J$5:$J$1000,$A17,'Document Checklist'!$B$5:$B$1000,"City Approval") -> 0 | H17: =COUNTIFS('Document Checklist'!$J$5:$J$1000,$A17,'Document Checklist'!$B$5:$B$1000,"Gift Deed") -> 0 | I17: =COUNTIFS('Document Checklist'!$J$5:$J$1000,$A17,'Document Checklist'!$B$5:$B$1000,"RERA") -> 0 | J17: =COUNTIFS('Document Checklist'!$J$5:$J$1000,$A17,'Document Checklist'!$B$5:$B$1000,"Plot Sale") -> 14 | K17: =SUM(C17:J17) -> 14
B18: Total | C18: =SUM(C5:C17) -> 16 | D18: =SUM(D5:D17) -> 17 | E18: =SUM(E5:E17) -> 11 | F18: =SUM(F5:F17) -> 11 | G18: =SUM(G5:G17) -> 14 | H18: =SUM(H5:H17) -> 10 | I18: =SUM(I5:I17) -> 15 | J18: =SUM(J5:J17) -> 16 | K18: =SUM(K5:K17) -> 110
A20: Task → Document mapping (one row per area, task and document)
A21: Sino | B21: Area Type | C21: Stage No | D21: Stage | E21: Task ID | F21: Short Name | G21: Checklist | H21: Doc ID | I21: Document / Item | J21: Mandatory
A22: 1 | B22: Village | C22: 1 | D22: Land Due Diligence | E22: V1.1 | F22: Land Records | G22: Agri NOC | H22: AGR-02 | I22: Patta and Chitta | J22: Yes
A23: 2 | B23: Village | C23: 1 | D23: Land Due Diligence | E23: V1.1 | F23: Land Records | G23: Agri NOC | H23: AGR-04 | I23: FMB sketch | J23: Yes
A24: 3 | B24: Village | C24: 1 | D24: Land Due Diligence | E24: V1.2 | F24: EC 30 Yrs | G24: Agri NOC | H24: AGR-05 | I24: Encumbrance Certificate (30+ years) | J24: Yes
A25: 4 | B25: Village | C25: 1 | D25: Land Due Diligence | E25: V1.3 | F25: Title Opinion | G25: Agri NOC | H25: AGR-06 | I25: Sale deed / parent title documents | J25: Yes
A26: 5 | B26: Village | C26: 1 | D26: Land Due Diligence | E26: V1.3 | F26: Title Opinion | G26: DTCP Approval | H26: DTC-04 | I26: Legal title opinion | J26: Yes
A27: 6 | B27: Village | C27: 2 | D27: Classification & Feasibility | E27: V2.1 | F27: Dry/Wet Check | G27: Agri NOC | H27: AGR-03 | I27: A-register / Adangal extract | J27: Yes
A28: 7 | B28: Village | C28: 2 | D28: Classification & Feasibility | E28: V2.1 | F28: Dry/Wet Check | G28: Agri NOC | H28: AGR-08 | I28: Site photographs (all sides) | J28: Yes
A29: 8 | B29: Village | C29: 2 | D29: Classification & Feasibility | E29: V2.1 | F29: Dry/Wet Check | G29: Agri NOC | H29: AGR-09 | I29: Land classification certificate | J29: Conditional
A30: 9 | B30: Village | C30: 3 | D30: Change of Land Use (CLU) | E30: V3.1 | F30: CLU Application | G30: Agri NOC | H30: AGR-01 | I30: Land-use conversion application form | J30: Yes
A31: 10 | B31: Village | C31: 3 | D31: Change of Land Use (CLU) | E31: V3.1 | F31: CLU Application | G31: Agri NOC | H31: AGR-12 | I31: Affidavit – no tenancy / not irrigated / no dispute | J31: Yes
A32: 11 | B32: Village | C32: 3 | D32: Change of Land Use (CLU) | E32: V3.1 | F32: CLU Application | G32: Agri NOC | H32: AGR-13 | I32: Owner ID and address proof (Aadhaar, PAN) | J32: Yes
A33: 12 | B33: Village | C33: 3 | D33: Change of Land Use (CLU) | E33: V3.1 | F33: CLU Application | G33: Agri NOC | H33: AGR-14 | I33: Power of Attorney | J33: Conditional
... A279: 258 | B279: City | C279: 13 | D279: Sub-division & Sale | E279: C13.4 | F279: Patta Transfer | G279: Plot Sale | H279: SAL-16 | I279: Patta transfer application / order | J279: Yes

Sheet Validation
A1: Validation Checks
A2: All checks must show OK before import.
A4: # | B4: Check | C4: Result | D4: Detail
A5: 1 | B5: Instalment percentages total 100 | C5: =IF(SUMIF('Additional Settings'!B5:B200,"Instalment",'Additional Settings'!E5:E200)=100,"OK","ERROR") -> OK | D5: ="Total = "&SUMIF('Additional Settings'!B5:B200,"Instalment",'Additional Settings'!E5:E200) -> Total = 100
A6: 2 | B6: Last instalment due ≤ Sale Completion Window | C6: =IF(SUMPRODUCT(MAX(('Additional Settings'!B5:B200="Instalment")*N(+'Additional Settings'!F5:F200)))<=SUMIF('Additional Settings'!C5:C200,"Sale Completion Window",'Additional Settings'!E5:E200),"OK","ERROR") -> OK | D6: ="Last due = "&SUMPRODUCT(MAX(('Additional Settings'!B5:B200="Instalment")*N(+'Additional Settings'!F5:F200)))&" working days, window = "&SUMIF('Additional Settings'!C5:C200,"Sale Completion Window",'Additional Settings'!E5:E200)&" days" -> Last due = 13 working days, window = 15 days
A7: 3 | B7: Percentage settings between 0 and 100 | C7: =IF(COUNTIFS('Additional Settings'!D5:D200,"Percentage",'Additional Settings'!E5:E200,">100")+COUNTIFS('Additional Settings'!D5:D200,"Percentage",'Additional Settings'!E5:E200,"<0")=0,"OK","ERROR") -> OK | D7: ="Out-of-range rows: "&(COUNTIFS('Additional Settings'!D5:D200,"Percentage",'Additional Settings'!E5:E200,">100")+COUNTIFS('Additional Settings'!D5:D200,"Percentage",'Additional Settings'!E5:E200,"<0")) -> Out-of-range rows: 0
A8: 4 | B8: All settings have a Unit Value | C8: =IF(COUNTA('Additional Settings'!C5:C200)=COUNTA('Additional Settings'!E5:E200),"OK","ERROR") -> OK | D8: ="Blank values: "&(COUNTA('Additional Settings'!C5:C200)-COUNTA('Additional Settings'!E5:E200)) -> Blank values: 0
A9: 5 | B9: Setting Sino unique | C9: =IF(SUMPRODUCT(('Additional Settings'!A5:A200<>"")/COUNTIF('Additional Settings'!A5:A200,'Additional Settings'!A5:A200&""))=COUNT('Additional Settings'!A5:A200),"OK","ERROR") -> OK | D9: =""
A10: 6 | B10: Tenant Profile – required fields filled | C10: =IF(COUNTIFS('Tenant Profile'!E5:E20,"Yes",'Tenant Profile'!D5:D20,"")=0,"OK","ERROR") -> ERROR | D10: ="Missing required: "&COUNTIFS('Tenant Profile'!E5:E20,"Yes",'Tenant Profile'!D5:D20,"") -> Missing required: 7
A11: 7 | B11: Pin Code is 6 digits | C11: =IF(AND(LEN('Tenant Profile'!D13)=6,ISNUMBER(--'Tenant Profile'!D13)),"OK","ERROR") -> ERROR | D11: ="Value: "&'Tenant Profile'!D13 -> Value:
A12: 8 | B12: Approval Task IDs unique | C12: =IF(SUMPRODUCT(('Approval Stages'!E5:E1000<>"")/COUNTIF('Approval Stages'!E5:E1000,'Approval Stages'!E5:E1000&""))=COUNTA('Approval Stages'!E5:E1000),"OK","ERROR") -> OK | D12: ="Tasks: "&COUNTA('Approval Stages'!E5:E1000) -> Tasks: 148
A13: 9 | B13: Approval durations are ≥ 0 | C13: =IF(COUNTIF('Approval Stages'!K5:K1000,"<0")=0,"OK","ERROR") -> OK | D13: =""
A14: 10 | B14: Facility IDs unique | C14: =IF(SUMPRODUCT(('Facility Master'!B5:B500<>"")/COUNTIF('Facility Master'!B5:B500,'Facility Master'!B5:B500&""))=COUNTA('Facility Master'!B5:B500),"OK","ERROR") -> OK | D14: ="Facilities: "&COUNTA('Facility Master'!B5:B500) -> Facilities: 40
A15: 11 | B15: Checklist Doc IDs unique | C15: =IF(SUMPRODUCT(('Document Checklist'!C5:C1000<>"")/COUNTIF('Document Checklist'!C5:C1000,'Document Checklist'!C5:C1000&""))=COUNTA('Document Checklist'!C5:C1000),"OK","ERROR") -> OK | D15: ="Documents: "&COUNTA('Document Checklist'!C5:C1000) -> Documents: 110
A16: 12 | B16: Every applicable document mapped to a Task ID | C16: =IF(COUNTIF('Document Checklist'!L5:N1000,"")-3*(1000-4-COUNTA('Document Checklist'!C5:C1000))=0,"OK","ERROR") -> OK | D16: =""
A17: 13 | B17: Mapped Task IDs exist in Approval Stages | C17: {=IF(SUMPRODUCT(('Document Checklist'!L5:N1000<>"")*('Document Checklist'!L5:N1000<>"N/A")*(COUNTIF('Approval Stages'!E5:E2000,'Document Checklist'!L5:N1000)=0))=0,"OK","ERROR")} -> OK | D17: =""
A18: 14 | B18: Every checklist has at least one item | C18: {=IF(SUMPRODUCT(--(COUNTIF('Document Checklist'!B5:B1000,Lists!F2:F9)=0))=0,"OK","ERROR")} -> OK | D18: =""
A19: 15 | B19: Users – at least one Admin | C19: =IF(COUNTIF(Users!E5:E54,"Admin")>=1,"OK","ERROR") -> ERROR | D19: ="Admins: "&COUNTIF(Users!E5:E54,"Admin") -> Admins: 0
A20: 16 | B20: Users – rows complete (name, email, mobile, role) | C20: =IF(SUMPRODUCT((COUNTA(Users!B5:B54)+COUNTA(Users!C5:C54)+COUNTA(Users!D5:D54)+COUNTA(Users!E5:E54))=4*COUNTA(Users!C5:C54))*(COUNTA(Users!C5:C54)>0),"OK","ERROR") -> ERROR | D20: ="Users: "&COUNTA(Users!C5:C54) -> Users: 0
A21: 17 | B21: Users – emails unique | C21: =IF(SUMPRODUCT((Users!C5:C54<>"")/COUNTIF(Users!C5:C54,Users!C5:C54&""))=COUNTA(Users!C5:C54),"OK","ERROR") -> OK | D21: =""
A22: 18 | B22: Users – mobiles are 10 digits | C22: =IF(SUMPRODUCT((Users!D5:D54<>"")*(LEN(Users!D5:D54)<>10))=0,"OK","ERROR") -> OK | D22: =""
A23: 19 | B23: Users – roles valid | C23: {=IF(SUMPRODUCT((Users!E5:E54<>"")*(COUNTIF(Lists!J2:J5,Users!E5:E54)=0))=0,"OK","ERROR")} -> OK | D23: =""
A24: 20 | B24: Notification Groups – at least one active | C24: =IF(COUNTIFS('Notification Groups'!B5:B100,"<>",'Notification Groups'!E5:E100,"Yes")>=1,"OK","ERROR") -> OK | D24: =""
A25: 21 | B25: Contact Number is 10 digits | C25: =IF(AND(LEN('Tenant Profile'!D14)=10,ISNUMBER(--'Tenant Profile'!D14)),"OK","ERROR") -> ERROR | D25: ="Value: "&'Tenant Profile'!D14 -> Value:
A26: 22 | B26: Facility unit costs are > 0 | C26: =IF(COUNTIFS('Facility Master'!D5:D500,"<>",'Facility Master'!K5:K500,"<=0")+COUNTIFS('Facility Master'!D5:D500,"<>",'Facility Master'!L5:L500,"<=0")+COUNTIFS('Facility Master'!D5:D500,"<>",'Facility Master'!M5:M500,"<=0")=0,"OK","ERROR") -> OK | D26: =""
B28: Overall status | C28: =IF(COUNTIF(C5:C26,"ERROR")=0,"READY","FIX ERRORS") -> FIX ERRORS

Sheet Lists
A1: Setting Type | B1: Setting Unit | C1: Area Type | D1: Tier Flag | E1: Yes/No | F1: Checklist | G1: Applies To | H1: Mandatory | I1: State | J1: Role | K1: Notification Type
A2: App Settings | B2: Code | C2: Village | D2: Y | E2: Yes | F2: Agri NOC | G2: All | H2: Yes | I2: Tamil Nadu | J2: Admin | K2: Email
A3: Instalment | B3: Percentage | C3: Town | D3: - | E3: No | F3: DTCP Approval | G3: Village | H3: Conditional | I3: Kerala | J3: Manager
B4: Days | C4: City | D4: Opt | F4: Local BDO Approval | G4: Town | H4: No | I4: Karnataka | J4: Sales
B5: Times | F5: Town Approval | G5: City | I5: Andhra Pradesh | J5: Accountant
F6: City Approval | G6: Town, City | I6: Telangana
F7: Gift Deed | I7: Puducherry
F8: RERA
F9: Plot Sale
